<?xml version="1.0" encoding="utf-8"?>
<robot name="Kinova_description">
  <link name="base_link">
    <inertial>
      <origin xyz="0.00077376 5.0345E-05 0.07815" rpy="0 0 0"/>
      <mass value="1.0621"/>
      <inertia ixx="0.0027558" ixy="-1.145E-07" ixz="2.8102E-05" iyy="0.00278" iyz="1.8269E-06" izz="0.0011531"/>
    </inertial>
    <visual>
      <origin xyz="0 0 0" rpy="0 0 0"/>
      <geometry><mesh filename="meshes/base_link.STL"/></geometry>
      <material name=""><color rgba="0.79216 0.81961 0.93333 1"/></material>
    </visual>
    <collision>
      <origin xyz="0 0 0" rpy="0 0 0"/>
      <geometry><mesh filename="meshes/base_link.STL"/></geometry>
    </collision>
  </link>

  <link name="link1">
    <inertial>
      <origin xyz="6.1995E-05 -0.088531 0.0047529" rpy="0 0 0"/>
      <mass value="0.31045"/>
      <inertia ixx="0.00015281" ixy="-1.983E-09" ixz="-3.2458E-14" iyy="0.00020135" iyz="3.7009E-14" izz="0.0002106"/>
    </inertial>
    <visual>
      <origin xyz="0 0 0" rpy="0 0 0"/>
      <geometry><mesh filename="meshes/link1.STL"/></geometry>
      <material name=""><color rgba="0.75294 0.75294 0.75294 1"/></material>
    </visual>
    <collision>
      <origin xyz="0 0 0" rpy="0 0 0"/>
      <geometry><mesh filename="meshes/link1.STL"/></geometry>
    </collision>
  </link>
  <joint name="joint1" type="revolute">
    <origin xyz="0 0 0.14045" rpy="-1.5708 0 0"/>
    <parent link="base_link"/>
    <child link="link1"/>
    <axis xyz="0 -1 0"/>
    <limit lower="-3.14" upper="3.14" effort="30" velocity="5"/>
    <dynamics damping="0.1" friction="0.1"/>
  </joint>

  <link name="link2">
    <inertial>
      <origin xyz="6.3307E-05 -0.017418 0.098831" rpy="0 0 0"/>
      <mass value="0.43942"/>
      <inertia ixx="0.00061383" ixy="1.0517E-08" ixz="2.2326E-08" iyy="0.00069605" iyz="-6.3782E-05" izz="0.00038569"/>
    </inertial>
    <visual>
      <origin xyz="0 0 0" rpy="0 0 0"/>
      <geometry><mesh filename="meshes/link2.STL"/></geometry>
      <material name=""><color rgba="0.75294 0.75294 0.75294 1"/></material>
    </visual>
    <collision>
      <origin xyz="0 0 0" rpy="0 0 0"/>
      <geometry><mesh filename="meshes/link2.STL"/></geometry>
    </collision>
  </link>
  <joint name="joint2" type="revolute">
    <origin xyz="0 -0.1434 0" rpy="1.5708 0 0"/>
    <parent link="link1"/>
    <child link="link2"/>
    <axis xyz="0 -1 0"/>
    <limit lower="-3.14" upper="3.14" effort="40" velocity="3"/>
    <dynamics damping="0.1" friction="0.1"/>
  </joint>

  <link name="link3">
    <inertial>
      <origin xyz="-6.1791E-06 -0.12985 0.0066902" rpy="0 0 0"/>
      <mass value="0.43861"/>
      <inertia ixx="0.0012106" ixy="2.2988E-08" ixz="-7.9414E-09" iyy="0.00038569" iyz="7.8742E-05" izz="0.0012914"/>
    </inertial>
    <visual>
      <origin xyz="0 0 0" rpy="0 0 0"/>
      <geometry><mesh filename="meshes/link3.STL"/></geometry>
      <material name=""><color rgba="0.75294 0.75294 0.75294 1"/></material>
    </visual>
    <collision>
      <origin xyz="0 0 0" rpy="0 0 0"/>
      <geometry><mesh filename="meshes/link3.STL"/></geometry>
    </collision>
  </link>
  <joint name="joint3" type="revolute">
    <origin xyz="6.1995E-05 -0.010643 0.1956" rpy="-1.5708 0 0"/>
    <parent link="link2"/>
    <child link="link3"/>
    <axis xyz="0 -1 0"/>
    <limit lower="-3.14" upper="3.14" effort="30" velocity="5"/>
    <dynamics damping="0.1" friction="0.1"/>
  </joint>

  <link name="link4">
    <inertial>
      <origin xyz="3.0089E-07 0.00016564 0.07622" rpy="0 0 0"/>
      <mass value="0.35459"/>
      <inertia ixx="0.00049578" ixy="4.2406E-09" ixz="-4.0692E-08" iyy="0.00057354" iyz="-5.777E-05" izz="0.00022825"/>
    </inertial>
    <visual>
      <origin xyz="0 0 0" rpy="0 0 0"/>
      <geometry><mesh filename="meshes/link4.STL"/></geometry>
      <material name=""><color rgba="0.75294 0.75294 0.75294 1"/></material>
    </visual>
    <collision>
      <origin xyz="0 0 0" rpy="0 0 0"/>
      <geometry><mesh filename="meshes/link4.STL"/></geometry>
    </collision>
  </link>
  <joint name="joint4" type="revolute">
    <origin xyz="0 -0.2242 -0.0202" rpy="1.5708 0 0"/>
    <parent link="link3"/>
    <child link="link4"/>
    <axis xyz="0 -1 0"/>
    <limit lower="-3.14" upper="3.14" effort="30" velocity="5"/>
    <dynamics damping="0.1" friction="0.1"/>
  </joint>

  <link name="link5">
    <inertial>
      <origin xyz="-1.4448E-07 -0.050174 0.0092547" rpy="0 0 0"/>
      <mass value="0.25081"/>
      <inertia ixx="0.0001993" ixy="6.7087E-10" ixz="2.2658E-09" iyy="0.00013442" iyz="2.2082E-05" izz="0.00021605"/>
    </inertial>
    <visual>
      <origin xyz="0 0 0" rpy="0 0 0"/>
      <geometry><mesh filename="meshes/link5.STL"/></geometry>
      <material name=""><color rgba="0.75294 0.75294 0.75294 1"/></material>
    </visual>
    <collision>
      <origin xyz="0 0 0" rpy="0 0 0"/>
      <geometry><mesh filename="meshes/link5.STL"/></geometry>
    </collision>
  </link>
  <joint name="joint5" type="revolute">
    <origin xyz="0 0.0084 0.2203" rpy="-1.5708 0 0"/>
    <parent link="link4"/>
    <child link="link5"/>
    <axis xyz="0 -1 0"/>
    <limit lower="-3.14" upper="3.14" effort="9" velocity="10"/>
    <dynamics damping="0.1" friction="0.1"/>
  </joint>

  <link name="link6">
    <inertial>
      <origin xyz="-9.215E-08 0.0034219 0.04541" rpy="0 0 0"/>
      <mass value="0.25081"/>
      <inertia ixx="0.00021273" ixy="-1.4755E-09" ixz="2.8166E-09" iyy="0.00022613" iyz="-3.0157E-05" izz="0.00013777"/>
    </inertial>
    <visual>
      <origin xyz="0 0 0" rpy="0 0 0"/>
      <geometry><mesh filename="meshes/link6.STL"/></geometry>
      <material name=""><color rgba="0.75294 0.75294 0.75294 1"/></material>
    </visual>
    <collision>
      <origin xyz="0 0 0" rpy="0 0 0"/>
      <geometry><mesh filename="meshes/link6.STL"/></geometry>
    </collision>
  </link>
  <joint name="joint6" type="revolute">
    <origin xyz="0 -0.0931 -0.01205" rpy="1.5708 0 0"/>
    <parent link="link5"/>
    <child link="link6"/>
    <axis xyz="0 -1 0"/>
    <limit lower="-3.14" upper="3.14" effort="9" velocity="10"/>
    <dynamics damping="0.1" friction="0.1"/>
  </joint>

  <link name="link7">
    <inertial>
      <origin xyz="-0.00014228 -0.015172 0.0087949" rpy="0 0 0"/>
      <mass value="0.16123"/>
      <inertia ixx="6.5029E-05" ixy="-3.2314E-07" ixz="1.0233E-07" iyy="0.00010702" iyz="-1.7595E-07" izz="8.0849E-05"/>
    </inertial>
    <visual>
      <origin xyz="0 0 0" rpy="0 0 0"/>
      <geometry><mesh filename="meshes/link7.STL"/></geometry>
      <material name=""><color rgba="0.75294 0.75294 0.75294 1"/></material>
    </visual>
    <collision>
      <origin xyz="0 0 0" rpy="0 0 0"/>
      <geometry><mesh filename="meshes/link7.STL"/></geometry>
    </collision>
  </link>
  <joint name="joint7" type="revolute">
    <origin xyz="0 0.01265 0.1178" rpy="-1.5708 0 0"/>
    <parent link="link6"/>
    <child link="link7"/>
    <axis xyz="0 -1 0"/>
    <limit lower="-3.14" upper="3.14" effort="9" velocity="10"/>
    <dynamics damping="0.1" friction="0.1"/>
  </joint>

  <link name="link_tool">
    <inertial>
      <origin xyz="-6.3933E-05 0.14705 1.8021E-05" rpy="0 0 0"/>
      <mass value="0.37712"/>
      <inertia ixx="0.00024605" ixy="-9.7451E-08" ixz="1.0852E-08" iyy="0.00016881" iyz="-1.1287E-07" izz="0.00028469"/>
    </inertial>
    <visual>
      <origin xyz="0 0 0" rpy="0 0 0"/>
      <geometry><mesh filename="meshes/link_tool.STL"/></geometry>
      <material name=""><color rgba="0.75294 0.75294 0.75294 1"/></material>
    </visual>
    <collision>
      <origin xyz="0 0 0" rpy="0 0 0"/>
      <geometry><mesh filename="meshes/link_tool.STL"/></geometry>
    </collision>
  </link>
  <joint name="joint_tool" type="fixed">
    <origin xyz="0 -0.26156 0" rpy="0 0 0"/>
    <parent link="link7"/>
    <child link="link_tool"/>
    <axis xyz="0 0 0"/>
  </joint>
</robot>